Workbook
Name tgr: 'DCF & Projected Price Terminal '!#REF!
Name wacc: 'DCF & Projected Price Terminal '!#REF!

Sheet DCF & Projected Price Terminal 
B2: DCF & Projected Price Terminal in M$
B3: =E5 -> NVDA
D4: Overview | F4: Market Value
D5: Ticker | E5: NVDA | F5: Cap. | G5: =E8*E9 -> 3493930.9
D6: Date | E6: 45816 | F6: (-) Cash & Equi | G6: =BS!CP5 -> 15234 | H6: Qick FS
D7: Year end | E7: 46022 | F7: **(+) Debt | G7: =BS!CP26+BS!CP28+BS!CP32+BS!CP33+BS!CP34 -> 10285 | H7: Qick FS
D8: Current SP | E8: 142.29 | F8: EV | G8: =G5-G6+G7 -> 3488981.9
D9: Outstanding (M) | E9: =IS!Z31 -> 24555 | F9: EV per Share | G9: =G8/E9 -> 142.08845
D10: KGV 2025 | E10: =E8/N124 -> 33.253334 | F10: EV/Revenue 2025 | G10: =G8/N41 -> 17.461586
D11: PEG-Ratio 2025 | E11: =E10/((N124/J124)^(1/5)-1)/100 -> 0.54108936 | F11: EV/EBIT 2025 | G11: =G8/N44 -> 28.27376
B12: Fill in -> = hard! | D12: Cap./Revenue 2025 | E12: =G5/N41 -> 17.486354
F13: **Relevant Debt for EV: LT Debt, ST Debt, Capital Lease Obligations, Current Portion of Capital Leases and Pension Liabilities
B14: DCF Calculation for Implied Share Price
B16: Assumptions
B18: Switches | C18: use | D18: Forecast 2029 (5y) | G18: Conservativ | H18: Base | I18: Optimistic | P18: WACC
B19: Assumptions | D19: Assumptions | F19: Year | G19: Metric 1 | H19: Metric 2 | I19: Metric 3 | P19: Base
B20: Revenue | C20: 1 | D20: Revenue | F20: "25-"27 | G20: *Forecast from Gurufocus | P20: Market Cap | R20: =G5 -> 3493930.9
B21: EBIT | C21: 1 | D21: Revenue Growth | E21: -> | F21: "28-"29 | G21: -0.1 | H21: -0.05 | I21: 0.1 | P21: % of Equity | R21: =R20/(R20+R27) -> 0.99706496
B22: WACC | C22: 1 | D22: EBIT | F22: "25-"27 | G22: *Forecast from Gurufocus | P22: Cost of Equity | R22: =R23+R24*R25 -> 0.135
B23: TGR | C23: 1 | D23: EBIT Growth | E23: -> | F23: "28-"29 | G23: 0 | H23: 0.015 | I23: 0.025 | P23: Risk Free Rate (10y US Treasury) | R23: 0.045 | S23: https://www.cnbc.com/quotes/US10Y
P24: Levered Beta (3y) | R24: 1.8 | S24: https://www.infrontanalytics.com/fe-DE/31436NU/NVIDIA-Corp-/Beta
B25: Valuation | D25: WACC | G25: =H25+0.01 -> 0.14971276 | H25: =R34+0.005 -> 0.13971276 | I25: =H25-0.01 -> 0.12971276 | P25: Market Risk Premium (ERP) | R25: 0.05 | S25: https://www.kroll.com/en/insights/publications/cost-of-capital/recommended-us-equity-risk-premium-and-corresponding-risk-free-rates
B26: WACC | C26: =CHOOSE(C22,G25,H25,I25) -> 0.14971276 | D26: TGR (US 2,0%; EU 1,5%; China 3,3%) | G26: =H26-0.002 -> 0.018 | H26: 0.02 | I26: =H26+0.002 -> 0.022 | P26: CAPM | R26: =R25+R23 -> 0.095
B27: TGR | C27: =CHOOSE(C23,G26,H26,I26) -> 0.018 | D27: Implied | P27: Debt | R27: =G7 -> 10285
D28: Implied Price per Share (hard) | F28: -> | G28: 80.6 | H28: 90.79 | I28: 105.82 | P28: % of Debt | R28: =R27/(R20+R27) -> 0.002935036
D29: Implied Upside/(Downside) | G29: =G28/E8-1 -> -0.4335512 | H29: =H28/E8-1 -> -0.36193689 | I29: =I28/E8-1 -> -0.25630754 | P29: Cost of Debt | R29: 0.0425 | S29: https://valueinvesting.io/NVDA/valuation/wacc | U29: or JA
D30: CAGR | G30: =(G28/E8)^(1/R62)-1 -> -0.12430384 | H30: =(H28/E8)^(1/R62)-1 -> -0.099615323 | I30: =(I28/E8)^(1/R62)-1 -> -0.066820115 | P30: Tax Rate | R30: =Q79 -> 0.12629613
D31: Projected
D32: Projected Price per Share | G32: =R140 -> 301.07422 | H32: =R141 -> 315.69094 | I32: =R142 -> 421.08988 | P32: Total | R32: =R27+R20 -> 3504215.9
D33: Upside/(Downside) to Current SP | G33: =G32/E8-1 -> 1.1159197 | H33: =H32/E8-1 -> 1.2186446 | I33: =I32/E8-1 -> 1.9593779
D34: CAGR | G34: =(G32/E8)^(1/R62)-1 -> 0.19128775 | H34: =(H32/E8)^(1/R62)-1 -> 0.20455019 | I34: =(I32/E8)^(1/R62)-1 -> 0.28837878 | P34: WACC | R34: =R21*R22+(R28*R29*(1-R30)) -> 0.13471276
D35: Cap. | G35: =G32*R102 -> 7467844.9 | H35: =H32*R102 -> 7830398.1 | I35: =I32*R102 -> 10444713
D37: Diff. Implied to Projected | G37: =G32-G28 -> 220.47422 | H37: =H32-H28 -> 224.90094 | I37: =I32-I28 -> 315.26988
B39: 2025-01 -> 2024 | J39: Total "15-"24 | K39: =M41/D41-1 -> 25.047305 | L39: CAGR "15-"24 | M39: =(M41/D41)^(1/9)-1 -> 0.43650446
B40: Income Statement | D40: 2015 | E40: =D40+1 -> 2016 | F40: =E40+1 -> 2017 | G40: =F40+1 -> 2018 | H40: =G40+1 -> 2019 | I40: =H40+1 -> 2020 | J40: =I40+1 -> 2021 | K40: =J40+1 -> 2022 | L40: =K40+1 -> 2023 | ... R40: =Q40+1 -> 2029
B41: Revenue | D41: =IS!P5 -> 5010 | E41: =IS!Q5 -> 6910 | F41: =IS!R5 -> 9714 | G41: =IS!S5 -> 11716 | H41: =IS!T5 -> 10918 | I41: =IS!U5 -> 16675 | J41: =IS!V5 -> 26914 | K41: =IS!W5 -> 26974 | ... M41: =IS!Y5 -> 130497 | N41: 199809 | O41: 251046 | P41: 284787 | Q41: *Forecast from Gurufocus
B42: % growth | E42: =E41/D41-1 -> 0.37924152 | F42: =F41/E41-1 -> 0.40578871 | G42: =G41/F41-1 -> 0.2060943 | H42: =H41/G41-1 -> -0.068111984 | I42: =I41/H41-1 -> 0.52729438 | J42: =J41/I41-1 -> 0.61403298 | K42: =K41/J41-1 -> 0.002229323 | L42: =L41/K41-1 -> 1.2585453 | ... P42: =P41/O41-1 -> 0.13440166 | Q42: https://www.gurufocus.com/stock/NVDA/financials
D43: =D40 -> 2015 | J43: Total "15-"24 | K43: =M44/D44-1 -> 91.771071 | L43: CAGR "15-"24 | M43: =(M44/D44)^(1/9)-1 -> 0.65425096
B44: EBIT (Operating Income/Operating Profit) | D44: =IS!P14 -> 878 | E44: =IS!Q14 -> 1937 | F44: =IS!R14 -> 3210 | G44: =IS!S14 -> 3804 | H44: =IS!T14 -> 2846 | I44: =IS!U14 -> 4532 | J44: =IS!V14 -> 10041 | K44: =IS!W14 -> 5577 | ... M44: =IS!Y14 -> 81453 | N44: 123400 | O44: 165097 | P44: 186704 | Q44: *Forecast from Gurufocus
B45: % of Revenue | D45: =D44/D41 -> 0.1752495 | E45: =E44/E41 -> 0.28031838 | F45: =F44/F41 -> 0.3304509 | G45: =G44/G41 -> 0.32468419 | H45: =H44/H41 -> 0.26067045 | I45: =I44/I41 -> 0.27178411 | J45: =J44/J41 -> 0.37307721 | K45: =K44/K41 -> 0.20675465 | ... P45: =P44/P41 -> 0.65559172 | Q45: https://www.gurufocus.com/stock/NVDA/financials
...

Sheet IS
A1: Income Statement
B3: 2002-01 | C3: 2003-01 | D3: 2004-01 | E3: 2005-01 | F3: 2006-01 | G3: 2007-01 | H3: 2008-01 | I3: 2009-01 | J3: 2010-01 | K3: 2011-01 | L3: 2012-01 | M3: 2013-01 | N3: 2014-01 | O3: 2015-01 | P3: 2016-01 | Q3: 2017-01 | R3: 2018-01 | S3: 2019-01 | T3: 2020-01 | U3: 2021-01 | V3: 2022-01 | W3: 2023-01 | X3: 2024-01 | Y3: 2025-01 | Z3: TTM
A5: Revenue | B5: 1369.471 | C5: 1909.447 | D5: 1822.945 | E5: 2010.033 | F5: 2375.687 | G5: 3068.771 | H5: 4097.86 | I5: 3424.859 | J5: 3326.445 | K5: 3543.309 | L5: 3997.93 | M5: 4280.159 | N5: 4130 | O5: 4682 | P5: 5010 | Q5: 6910 | R5: 9714 | S5: 11716 | T5: 10918 | U5: 16675 | V5: 26914 | W5: 26974 | X5: 60922 | Y5: 130497 | Z5: 148515
A6: Cost of Goods Sold | B6: 850.233 | C6: 1333.435 | D6: 1294.067 | E6: 1362.478 | F6: 1465.654 | G6: 1768.322 | H6: 2228.58 | I6: 2250.59 | J6: 2149.522 | K6: 2134.219 | L6: 1941.413 | M6: 2053.816 | N6: 1862 | O6: 2083 | P6: 2199 | Q6: 2847 | R6: 3892 | S6: 4545 | T6: 4150 | U6: 6279 | V6: 9439 | W6: 11618 | X6: 16621 | Y6: 32639 | Z6: 44394
A7: Gross Profit | B7: 519.238 | C7: 576.012 | D7: 528.878 | E7: 647.555 | F7: 910.033 | G7: 1300.449 | H7: 1869.28 | I7: 1174.269 | J7: 1176.923 | K7: 1409.09 | L7: 2056.517 | M7: 2226.343 | N7: 2268 | O7: 2599 | P7: 2811 | Q7: 4063 | R7: 5822 | S7: 7171 | T7: 6768 | U7: 10396 | V7: 17475 | W7: 15356 | X7: 44301 | Y7: 97858 | Z7: 104121
A9: Operating Expenses
A10: Sales, General, & Administrative | B10: 97.185 | C10: 207.153 | D10: 165.249 | E10: 204.159 | F10: 202.088 | G10: 293.53 | H10: 341.297 | I10: 362.222 | J10: 367.017 | K10: 361.513 | L10: 405.613 | M10: 430.822 | N10: 436 | O10: 480 | P10: 602 | Q10: 663 | R10: 815 | S10: 991 | T10: 1093 | U10: 1940 | V10: 2166 | W10: 2440 | X10: 2654 | Y10: 3491 | Z10: 3755
A11: Research & Development | B11: 153.92 | C11: 224.873 | D11: 269.972 | E11: 348.22 | F11: 357.123 | G11: 553.467 | H11: 691.637 | I11: 855.879 | J11: 908.851 | K11: 848.83 | L11: 1002.605 | M11: 1147.282 | N11: 1336 | O11: 1360 | P11: 1331 | Q11: 1463 | R11: 1797 | S11: 2376 | T11: 2829 | U11: 3924 | V11: 5268 | W11: 7339 | X11: 8675 | Y11: 12914 | Z11: 14183
A12: Special Charges
A13: Other Operating Expense | B13: 16.371 | F13: 14.158
A14: Operating Profit | B14: 251.762 | C14: 143.986 | D14: 93.657 | E14: 95.176 | F14: 336.664 | G14: 453.452 | H14: 836.346 | I14: -43.832 | J14: -98.945 | K14: 198.747 | L14: 648.299 | M14: 648.239 | N14: 496 | O14: 759 | P14: 878 | Q14: 1937 | R14: 3210 | S14: 3804 | T14: 2846 | U14: 4532 | V14: 10041 | W14: 5577 | X14: 32972 | Y14: 81453 | Z14: 86183
A16: Net Interest Income | I16: 42.453 | J16: 19.795 | K16: 15.93 | L16: 16.06 | M16: 16.614 | N16: 7 | O16: -18 | P16: -8 | Q16: -4 | R16: 8 | S16: 78 | T16: 126 | U16: -127 | V16: -207 | W16: 5 | X16: 609 | Y16: 1539 | Z16: 1696
A17: Other Income (Expense) | B17: 0.987 | C17: 6.571 | D17: -6.984 | E17: 11.852 | F17: 20.124 | G17: 41.028 | H17: 64.995 | I17: -41.575 | J17: -3.144 | K17: 56.492 | L17: -0.963 | M17: -2.814 | N17: 7 | O17: 14 | P17: -127 | Q17: -28 | R17: -22 | S17: 14 | T17: -2 | U17: 4 | V17: 107 | W17: -1401 | X17: 237 | Y17: 1034 | Z17: 778
A18: Pre-Tax Profit | B18: 252.749 | C18: 150.557 | D18: 86.673 | E18: 107.028 | F18: 356.788 | G18: 494.48 | H18: 901.341 | I18: -42.954 | J18: -82.294 | K18: 271.169 | L18: 663.396 | M18: 662.039 | N18: 510 | O18: 755 | P18: 743 | Q18: 1905 | R18: 3196 | S18: 3896 | T18: 2970 | U18: 4409 | V18: 9941 | W18: 4181 | X18: 33818 | Y18: 84026 | Z18: 88657
A20: Income Tax | B20: -75.825 | C20: -59.758 | D20: -12.254 | E20: -18.413 | F20: -55.612 | G20: -46.35 | H20: -103.696 | I20: 12.913 | J20: 14.307 | K20: -18.023 | L20: -82.306 | M20: -99.503 | N20: -70 | O20: -124 | P20: -129 | Q20: -239 | R20: -149 | S20: 245 | T20: -174 | U20: -77 | V20: -189 | W20: 187 | X20: -4058 | Y20: -11146 | Z20: -11883
A21: Net Income from Continuing Ops. | B21: 176.924 | C21: 90.799 | D21: 74.419 | E21: 88.615 | F21: 301.176 | G21: 448.13 | H21: 797.645 | I21: -30.041 | J21: -67.987 | K21: 253.146 | L21: 581.09 | M21: 562.536 | N21: 440 | O21: 631 | P21: 614 | Q21: 1666 | R21: 3047 | S21: 4141 | T21: 2796 | U21: 4332 | V21: 9752 | W21: 4368 | X21: 29760 | Y21: 72880 | Z21: 76774
A23: Net Income from Discontinued Ops.
A24: Minority Interest
A25: Other Items | B25: 2.8421709e-14 | C25: 2.8421709e-14 | E25: -1.4210855e-14 | G25: 0.704 | L25: 1.1368684e-13
A26: Net Income | B26: 176.924 | C26: 90.799 | D26: 74.419 | E26: 88.615 | F26: 301.176 | G26: 448.834 | H26: 797.645 | I26: -30.041 | J26: -67.987 | K26: 253.146 | L26: 581.09 | M26: 562.536 | N26: 440 | O26: 631 | P26: 614 | Q26: 1666 | R26: 3047 | S26: 4141 | T26: 2796 | U26: 4332 | V26: 9752 | W26: 4368 | X26: 29760 | Y26: 72880 | Z26: 76774
A28: Basic EPS | B28: 0.01 | C28: 0.01 | E28: 0.01 | F28: 0.02 | G28: 0.02 | H28: 0.04 | K28: 0.01 | L28: 0.02 | M28: 0.02 | N28: 0.02 | O28: 0.03 | P28: 0.03 | Q28: 0.08 | R28: 0.13 | S28: 0.17 | T28: 0.12 | U28: 0.18 | V28: 0.39 | W28: 0.18 | X28: 1.21 | Y28: 2.97 | Z28: 3.14
A29: Diluted EPS | B29: 0.01 | C29: 0.01 | F29: 0.01 | G29: 0.02 | H29: 0.03 | K29: 0.01 | L29: 0.02 | M29: 0.02 | N29: 0.02 | O29: 0.03 | P29: 0.03 | Q29: 0.06 | R29: 0.12 | S29: 0.17 | T29: 0.11 | U29: 0.17 | V29: 0.39 | W29: 0.17 | X29: 1.19 | Y29: 2.94 | Z29: 3.1
A31: Basic Shares Outstanding | B31: 17153.223 | C31: 18412.354 | D31: 19301.229 | E31: 19917.481 | F31: 20352.624 | G31: 21133.673 | H31: 22004.32 | I31: 21925.04 | J31: 21982.96 | K31: 23007.08 | L31: 24145.84 | M31: 24772.96 | N31: 23520 | O31: 22080 | P31: 21720 | Q31: 21640 | R31: 23960 | S31: 24320 | T31: 24390 | U31: 24670 | V31: 24960 | W31: 24870 | X31: 24690 | Y31: 24555 | Z31: 24555
A32: Diluted Shares Outstanding | B32: 20518.621 | C32: 20197.061 | D32: 20714.483 | E32: 21086.897 | F32: 21931.274 | G32: 23478.501 | H32: 24269.28 | I32: 21925.04 | J32: 21982.96 | K32: 23547.36 | L32: 24654.84 | M32: 24998.28 | N32: 23800 | O32: 22520 | P32: 22760 | Q32: 25960 | R32: 25280 | S32: 25000 | T32: 24720 | U32: 25100 | V32: 25350 | W32: 25070 | X32: 24940 | Y32: 24804 | Z32: 24804
A34: EBITDA
A35: Operating Profit | B35: ='[1]Income Statement'!B14 -> 251.762 | C35: ='[1]Income Statement'!C14 -> 143.986 | D35: ='[1]Income Statement'!D14 -> 93.657 | E35: ='[1]Income Statement'!E14 -> 95.176 | F35: ='[1]Income Statement'!F14 -> 336.664 | G35: ='[1]Income Statement'!G14 -> 453.452 | H35: ='[1]Income Statement'!H14 -> 836.346 | I35: ='[1]Income Statement'!I14 -> -43.832 | ... Z35: ='[1]Income Statement'!Z14 -> 86183
A36: Plus: Depreciation & Amortization | B36: ='[1]Cash Flow Statement'!B7 -> 43.497 | C36: ='[1]Cash Flow Statement'!C7 -> 58.216 | D36: ='[1]Cash Flow Statement'!D7 -> 82.688 | E36: ='[1]Cash Flow Statement'!E7 -> 102.597 | F36: ='[1]Cash Flow Statement'!F7 -> 97.977 | G36: ='[1]Cash Flow Statement'!G7 -> 107.562 | H36: ='[1]Cash Flow Statement'!H7 -> 133.192 | I36: ='[1]Cash Flow Statement'!I7 -> 185.023 | ... Z36: ='[1]Cash Flow Statement'!Z7 -> 2065
A37: EBITDA | B37: =B35+B36 -> 295.259 | C37: =C35+C36 -> 202.202 | D37: =D35+D36 -> 176.345 | E37: =E35+E36 -> 197.773 | F37: =F35+F36 -> 434.641 | G37: =G35+G36 -> 561.014 | H37: =H35+H36 -> 969.538 | I37: =I35+I36 -> 141.191 | ... Z37: =Z35+Z36 -> 88248

Sheet CFS 
A1: Cash Flow Statement
B3: 2002-01 | C3: 2003-01 | D3: 2004-01 | E3: 2005-01 | F3: 2006-01 | G3: 2007-01 | H3: 2008-01 | I3: 2009-01 | J3: 2010-01 | K3: 2011-01 | L3: 2012-01 | M3: 2013-01 | N3: 2014-01 | O3: 2015-01 | P3: 2016-01 | Q3: 2017-01 | R3: 2018-01 | S3: 2019-01 | T3: 2020-01 | U3: 2021-01 | V3: 2022-01 | W3: 2023-01 | X3: 2024-01 | Y3: 2025-01 | Z3: TTM
A5: Net Income | B5: 176.924 | C5: 90.799 | D5: 74.419 | E5: 88.615 | F5: 301.176 | G5: 448.834 | H5: 797.645 | I5: -30.041 | J5: -67.987 | K5: 253.146 | L5: 581.09 | M5: 562.536 | N5: 440 | O5: 631 | P5: 614 | Q5: 1666 | R5: 3047 | S5: 4141 | T5: 2796 | U5: 4332 | V5: 9752 | W5: 4368 | X5: 29760 | Y5: 72880 | Z5: 76774
A7: Depreciation, Depletion, & Amortization | B7: 43.497 | C7: 58.216 | D7: 82.688 | E7: 102.597 | F7: 97.977 | G7: 107.562 | H7: 133.192 | I7: 185.023 | J7: 196.664 | K7: 187 | L7: 204.2 | M7: 226 | N7: 237 | O7: 220 | P7: 197 | Q7: 186 | R7: 199 | S7: 262 | T7: 380 | U7: 1098 | V7: 1174 | W7: 1543 | X7: 1508 | Y7: 1864 | Z7: 2065
A8: Change in Receivables | B8: -43.806 | C8: -9.07 | D8: -41.356 | E8: -110.312 | F8: -21.415 | G8: -175.261 | H8: -146.055 | I8: 348.873 | J8: -56.741 | K8: 26.341 | L8: 26.236 | M8: -118.94 | N8: 29 | O8: -49 | P8: -32 | Q8: -321 | R8: -440 | S8: -149 | T8: -233 | U8: -550 | V8: -2215 | W8: 822 | X8: -6172 | Y8: -13063 | Z8: -9764
A9: Change in Inventory | B9: -123.497 | C9: 68.831 | D9: -85.126 | E9: -80.906 | F9: 60.916 | G9: -91.395 | H9: -3.69 | I9: -177.295 | J9: 204.656 | K9: -14.128 | L9: 18.884 | M9: -78.949 | N9: 25 | O9: -95 | P9: 66 | Q9: -375 | S9: -776 | T9: 597 | U9: -524 | V9: -774 | W9: -2554 | X9: -98 | Y9: -4781 | Z9: -5462
A10: Change in Prepaid Assets | B10: -37.739 | C10: 33.701 | D10: -2.698 | E10: -5.569 | F10: -4.568 | G10: -5.294 | H10: -6.293 | I10: 21.528 | J10: 5.437 | K10: 12.859 | L10: -85.497 | M10: -11.723 | N10: 12 | O10: 4 | P10: -16 | Q10: -18 | R10: 21 | S10: -55 | T10: 77 | U10: -394 | V10: -1715 | W10: -1517 | X10: -1522 | Y10: -395 | Z10: 891
A11: Change in Other Working Capital | B11: 106.599 | C11: -58.06 | D11: -51.588 | E11: 100.608 | F11: -18.144 | G11: 139.08 | H11: 325.987 | I11: -226.439 | J11: -16.937 | K11: 126.627 | L11: 42.526 | M11: 97.29 | N11: -53 | O11: -63 | P11: -69 | Q11: 35 | R11: 604 | S11: 123 | T11: 276 | U11: 765 | V11: 1341 | W11: 1042 | X11: 4070 | Y11: 8856 | Z11: 12772
A12: Change in Working Capital (Total) | B12: -98.443 | C12: 35.402 | D12: -180.768 | E12: -96.179 | F12: 16.789 | G12: -132.87 | H12: 169.949 | I12: -33.333 | J12: 136.415 | K12: 151.699 | L12: 2.149 | M12: -112.322 | N12: 13 | O12: -203 | P12: -51 | Q12: -679 | R12: 185 | S12: -857 | T12: 717 | U12: -703 | V12: -3363 | W12: -2207 | X12: -3722 | Y12: -9383 | Z12: -1563
A13: Change in Deferred Tax | B13: -51.914 | C13: 29.768 | D13: 55.135 | E13: 8.694 | F13: -2.691 | G13: 41.766 | H13: 89.516 | I13: -23.277 | J13: -21.147 | K13: -2.646 | L13: 19.056 | M13: 31.86 | N13: 15 | O13: 83 | P13: 134 | Q13: 197 | R13: -359 | S13: -315 | T13: 18 | U13: -282 | V13: -406 | W13: -2164 | X13: -2489 | Y13: -4477 | Z13: -5077
A14: Stock-Based Compensation | I14: 162.706 | J14: 242.826 | K14: 100.353 | L14: 136.354 | M14: 136.662 | N14: 136 | O14: 158 | P14: 204 | Q14: 247 | R14: 391 | S14: 557 | T14: 844 | U14: 1397 | V14: 2004 | W14: 2709 | X14: 3549 | Y14: 4737 | Z14: 5200
A15: Other Cash from Operations | B15: 90.742 | C15: 50.847 | D15: 18.204 | E15: 28.473 | F15: 33.157 | G15: 121.819 | H15: 79.894 | I15: -11.718 | J15: 1.036 | K15: -13.755 | L15: -33.693 | M15: -20.564 | N15: -6 | O15: 17 | P15: 77 | Q15: 55 | R15: 39 | S15: -45 | T15: 6 | U15: -20 | V15: -53 | W15: 1392 | X15: -516 | Y15: -1532 | Z15: -1241
A16: Net Operating Cash Flow | B16: 160.806 | C16: 265.032 | D16: 49.678 | E16: 132.2 | F16: 446.408 | G16: 587.111 | H16: 1270.196 | I16: 249.36 | J16: 487.807 | K16: 675.797 | L16: 909.156 | M16: 824.172 | N16: 835 | O16: 906 | P16: 1175 | Q16: 1672 | R16: 3502 | S16: 3743 | T16: 4761 | U16: 5822 | V16: 9108 | W16: 5641 | X16: 28090 | Y16: 64089 | Z16: 76158
A18: Net Purchases of PP&E | B18: -161.075 | C18: -63.123 | D18: -127.604 | E18: -67.261 | F18: -79.6 | G18: -145.256 | H18: -187.745 | I18: -407.67 | J18: -77.601 | K18: -97.89 | L18: -138.735 | M18: -183.309 | N18: -230 | O18: -101 | P18: -79 | Q18: -169 | R18: -591 | S18: -600 | T18: -489 | U18: -1128 | V18: -976 | W18: -1833 | X18: -1069 | Y18: -3236 | Z18: -4094
A19: Net Cash From Acquisitions and Divestitures | I19: -27.948 | L19: -348.884 | N19: -17 | T19: -4 | U19: -8524 | V19: -263 | W19: -49 | X19: -83 | Y19: -1007 | Z19: -1351
A20: Net Purchases of Investments | B20: -457.597 | C20: -217.3 | D20: 286.948 | E20: -84.692 | F20: 59.628 | G20: 6.233 | H20: -498.031 | I20: 226.693 | J20: -441.514 | K20: -549.625 | L20: -654.155 | M20: -561.035 | N20: -554 | O20: -625 | P20: -345 | Q20: -624 | R20: 1869 | S20: -3497 | T20: 6638 | U20: -10023 | V20: -8591 | W20: 9257 | X20: -9290 | Y20: -16200 | Z20: -14521
A21: Net Purchases of Intangible Assets
A22: Other Cash from Investing | B22: 17.5 | C22: 3.099 | D22: -71.303 | E22: -2.8421709e-14 | F22: -21.815 | G22: -401.8 | H22: -75.542 | I22: -0.442 | J22: -0.218 | K22: -2.163 | L22: -1.59 | M22: 0.352 | N22: -5 | O22: -1 | P22: 24 | X22: -124 | Y22: 22 | Z22: 22
A23: Net Investing Cash Flow | B23: -601.172 | C23: -277.324 | D23: 88.041 | E23: -151.953 | F23: -41.787 | G23: -540.823 | H23: -761.318 | I23: -209.367 | J23: -519.333 | K23: -649.678 | L23: -1143.364 | M23: -743.992 | N23: -806 | O23: -727 | P23: -400 | Q23: -793 | R23: 1278 | S23: -4097 | T23: 6145 | U23: -19675 | V23: -9830 | W23: 7375 | X23: -10566 | Y23: -20421 | Z23: -19944
A25: Net Issuance of Common Stock | B25: 90.375 | C25: 25.487 | D25: 37.757 | E25: 17.858 | F25: -61.012 | G25: -53.818 | H25: -326.543 | I25: -350.089 | J25: 138.029 | K25: 177.276 | M25: -100 | N25: -887 | O25: -814 | P25: -587 | Q25: -739 | R25: -909 | S25: -1579 | W25: -10039 | X25: -9533 | Y25: -33706 | Z25: -40061
A26: Net Issuance of Preferred Stock
A27: Net Issuance of Debt | B27: -2.455 | C27: -4.935 | D27: -8.048 | E27: -4.015 | F27: -0.856 | J27: -0.929 | K27: -0.571 | L27: -1.608 | M27: -2.049 | N27: 1476 | Q27: 1315 | R27: -812 | S27: -16 | U27: 4968 | V27: 3977 | X27: -1250 | Y27: -1250
A28: Cash Paid for Dividends | M28: -46.866 | N28: -181 | O28: -186 | P28: -213 | Q28: -261 | R28: -341 | S28: -371 | T28: -390 | U28: -395 | V28: -399 | W28: -398 | X28: -395 | Y28: -834 | Z28: -980
A29: Other Cash from Financing | B29: 11.171 | C29: 5.734 | D29: -300 | E29: -3.5527137e-15 | F29: 0.491 | G29: 0.188 | H29: 0.22 | I29: 0.815 | J29: -76.041 | K29: 15.316 | L29: 238.331 | M29: 133.645 | N29: -18 | O29: 166 | P29: 124 | Q29: -24 | R29: -482 | S29: -900 | T29: -402 | U29: -769 | V29: -1713 | W29: -1180 | X29: -2455 | Y29: -6569 | Z29: -7526
A30: Net Financing Cash Flow | B30: 99.091 | C30: 26.286 | D30: -270.291 | E30: 13.843 | F30: -61.377 | G30: -53.63 | H30: -326.323 | I30: -349.274 | J30: 61.059 | K30: 192.021 | L30: 236.723 | M30: -15.27 | N30: 390 | O30: -834 | P30: -676 | Q30: 291 | R30: -2544 | S30: -2866 | T30: -792 | U30: 3804 | V30: 1865 | W30: -11617 | X30: -13633 | Y30: -42359 | Z30: -48567
A32: Free Cash Flow
A33: Cash from Operations | B33: =B16 -> 160.806 | C33: =C16 -> 265.032 | D33: =D16 -> 49.678 | E33: =E16 -> 132.2 | F33: =F16 -> 446.408 | G33: =G16 -> 587.111 | H33: =H16 -> 1270.196 | I33: =I16 -> 249.36 | ... Z33: =Z16 -> 76158
A34: Less: Capital Exenditures | B34: =B18 -> -161.075 | C34: =C18 -> -63.123 | D34: =D18 -> -127.604 | E34: =E18 -> -67.261 | F34: =F18 -> -79.6 | G34: =G18 -> -145.256 | H34: =H18 -> -187.745 | I34: =I18 -> -407.67 | ... Z34: =Z18 -> -4094
A35: Free Cash Flow | B35: =B33+B34 -> -0.269 | C35: =C33+C34 -> 201.909 | D35: =D33+D34 -> -77.926 | E35: =E33+E34 -> 64.939 | F35: =F33+F34 -> 366.808 | G35: =G33+G34 -> 441.855 | H35: =H33+H34 -> 1082.451 | I35: =I33+I34 -> -158.31 | ... Z35: =Z33+Z34 -> 72064

Sheet BS
A1: Balance Sheet
B3: 2002-04 | C3: 2002-07 | D3: 2002-10 | E3: 2003-01 | F3: 2003-04 | G3: 2003-07 | H3: 2003-10 | I3: 2004-01 | J3: 2004-04 | K3: 2004-07 | L3: 2004-10 | M3: 2005-01 | N3: 2005-04 | O3: 2005-07 | P3: 2005-10 | Q3: 2006-01 | R3: 2006-04 | S3: 2006-07 | T3: 2006-10 | U3: 2007-01 | V3: 2007-04 | W3: 2007-07 | X3: 2007-10 | Y3: 2008-01 | Z3: 2008-04 | AA3: 2008-07 | AB3: 2008-10 | AC3: 2009-01 | AD3: 2009-04 | AE3: 2009-07 | AF3: 2009-10 | AG3: 2010-01 | AH3: 2010-04 | AI3: 2010-07 | AJ3: 2010-10 | AK3: 2011-01 | AL3: 2011-04 | AM3: 2011-07 | AN3: 2011-10 | AO3: 2012-01 | AP3: 2012-04 | AQ3: 2012-07 | AR3: 2012-10 | AS3: 2013-01 | AT3: 2013-04 | AU3: 2013-07 | AV3: 2013-10 | AW3: 2014-01 | AX3: 2014-04 | AY3: 2014-07 | AZ3: 2014-10 | BA3: 2015-01 | BB3: 2015-04 | BC3: 2015-07 | BD3: 2015-10 | BE3: 2016-01 | BF3: 2016-04 | BG3: 2016-07 | BH3: 2016-10 | BI3: 2017-01 | BJ3: 2017-04 | BK3: 2017-07 | BL3: 2017-10 | BM3: 2018-01 | BN3: 2018-04 | BO3: 2018-07 | BP3: 2018-10 | BQ3: 2019-01 | BR3: 2019-04 | BS3: 2019-07 | BT3: 2019-10 | BU3: 2020-01 | BV3: 2020-04 | BW3: 2020-07 | BX3: 2020-10 | BY3: 2021-01 | BZ3: 2021-04 | CA3: 2021-07 | CB3: 2021-10 | CC3: 2022-01 | CD3: 2022-04 | CE3: 2022-07 | CF3: 2022-10 | CG3: 2023-01 | CH3: 2023-04 | CI3: 2023-07 | CJ3: 2023-10 | CK3: 2024-01 | CL3: 2024-04 | CM3: 2024-07 | CN3: 2024-10 | CO3: 2025-01 | CP3: 2025-04
A4: Assets
A5: Cash and Equivalents | B5: 307.151 | C5: 246.816 | D5: 322.535 | E5: 346.994 | F5: 278.796 | G5: 274.297 | H5: 231.813 | I5: 214.422 | J5: 196.675 | K5: 180.579 | L5: 156.687 | M5: 208.512 | N5: 281.004 | O5: 242.17 | P5: 364.308 | Q5: 551.756 | R5: 487.763 | S5: 388.423 | T5: 741.746 | U5: 544.414 | V5: 678.951 | W5: 914.745 | X5: 1056.702 | Y5: 726.969 | Z5: 803.308 | AA5: 719.143 | AB5: 461.253 | AC5: 417.688 | AD5: 512.274 | AE5: 523.785 | AF5: 614.49 | AG5: 447.221 | AH5: 447.262 | AI5: 377.003 | AK5: 665.361 | AL5: 683.633 | AM5: 532.614 | AN5: 566.816 | AO5: 667.876 | AP5: 369.135 | AQ5: 499.618 | AR5: 525.388 | AS5: 732.786 | AT5: 561.423 | AU5: 591.321 | AV5: 562.084 | AW5: 1151.587 | AX5: 509.165 | AY5: 515.092 | AZ5: 394.683 | BA5: 497 | BB5: 464 | BC5: 435 | BD5: 471 | BE5: 596 | BF5: 547 | BG5: 426 | BH5: 1940 | BI5: 1766 | BJ5: 1989 | BK5: 1988 | BL5: 2802 | BM5: 4002 | BN5: 765 | BO5: 718 | BP5: 721 | BQ5: 782 | BR5: 2772 | BS5: 7105 | BT5: 9765 | BU5: 10896 | BV5: 15494 | BW5: 3274 | BX5: 2251 | BY5: 847 | BZ5: 978 | CA5: 5628 | CB5: 1288 | CC5: 1990 | CD5: 3887 | CE5: 3013 | CF5: 2800 | CG5: 3389 | CH5: 5079 | CI5: 5783 | CJ5: 5519 | CK5: 7280 | CL5: 7587 | CM5: 8563 | CN5: 9107 | CO5: 8589 | CP5: 15234
A6: Short-Term Investments | B6: 521.246 | C6: 579.595 | D6: 589.042 | E6: 681.419 | F6: 771.542 | G6: 737.29 | H6: 380.313 | I6: 389.621 | J6: 460.628 | K6: 432.745 | L6: 431.163 | M6: 461.533 | N6: 450.508 | O6: 475.376 | P6: 421.87 | Q6: 398.418 | R6: 467.29 | S6: 462.744 | T6: 431.849 | U6: 573.436 | V6: 628.073 | W6: 656.818 | X6: 796.251 | Y6: 1082.509 | Z6: 818.331 | AA6: 938.087 | AB6: 843.635 | AC6: 837.702 | AD6: 825.873 | AE6: 942.32 | AF6: 1019.589 | AG6: 1281.006 | AH6: 1317.634 | AI6: 1395.497 | AK6: 1825.202 | AL6: 2042.908 | AM6: 1941.882 | AN6: 2181.538 | AO6: 2461.7 | AP6: 2761.677 | AQ6: 2778.482 | AR6: 2909.384 | AS6: 2995.097 | AT6: 3151.928 | AU6: 2344.572 | AV6: 2470.87 | AW6: 3520.223 | AX6: 3838.652 | AY6: 3870.962 | AZ6: 3846.114 | BA6: 4126 | BB6: 4328 | BC6: 4070 | BD6: 4257 | BE6: 4441 | BF6: 4207 | BG6: 4453 | BH6: 4731 | BI6: 5032 | BJ6: 4217 | BK6: 3889 | BL6: 3518 | BM6: 3106 | BN6: 6535 | BO6: 7225 | BP6: 6870 | BQ6: 6640 | BR6: 5030 | BS6: 1370 | BT6: 4 | BU6: 1 | BV6: 860 | BW6: 7707 | BX6: 7888 | BY6: 10714 | BZ6: 11689 | CA6: 14026 | CB6: 18010 | CC6: 19218 | CD6: 16451 | CE6: 14023 | CF6: 10343 | CG6: 9907 | CH6: 10241 | CI6: 10240 | CJ6: 12762 | CK6: 18704 | CL6: 23851 | CM6: 26237 | CN6: 29380 | CO6: 34621 | CP6: 37457
A7: Accounts Receivable | B7: 151.429 | C7: 133.038 | D7: 149.861 | E7: 154.501 | F7: 155.751 | G7: 190.213 | H7: 157.839 | I7: 196.631 | J7: 205.308 | K7: 246.396 | L7: 307.409 | M7: 296.279 | N7: 255.252 | O7: 355.393 | P7: 351.737 | Q7: 318.186 | R7: 391.27 | S7: 459.636 | T7: 439.252 | U7: 518.68 | V7: 471.519 | W7: 508.435 | X7: 552.407 | Y7: 666.494 | Z7: 651.8 | AA7: 679.416 | AB7: 607.834 | AC7: 318.435 | AD7: 304.393 | AE7: 351.96 | AF7: 397.82 | AG7: 374.963 | AH7: 529.663 | AI7: 395.934 | AK7: 348.77 | AL7: 343.202 | AM7: 419.944 | AN7: 371.261 | AO7: 336.143 | AP7: 411.155 | AQ7: 445.312 | AR7: 444.944 | AS7: 454.252 | AT7: 346.998 | AU7: 418.123 | AV7: 447.631 | AW7: 426.357 | AX7: 396.438 | AY7: 469.625 | AZ7: 563.4 | BA7: 474 | BB7: 455 | BC7: 514 | BD7: 536 | BE7: 505 | BF7: 523 | BG7: 644 | BH7: 833 | BI7: 826 | BJ7: 976 | BK7: 1213 | BL7: 1167 | BM7: 1265 | BN7: 1220 | BO7: 1662 | BP7: 2219 | BQ7: 1424 | BR7: 1242 | BS7: 1561 | BT7: 1455 | BU7: 1657 | BV7: 1907 | BW7: 2084 | BX7: 2546 | BY7: 2429 | BZ7: 3024 | CA7: 3586 | CB7: 3954 | CC7: 4650 | CD7: 5438 | CE7: 5317 | CF7: 4908 | CG7: 3827 | CH7: 4080 | CI7: 7066 | CJ7: 8309 | CL7: 12365 | CM7: 14132 | CN7: 17693 | CO7: 23065 | CP7: 22132
A8: Inventories | B8: 253.927 | C8: 285.35 | D8: 205.043 | E8: 145.046 | F8: 165.785 | G8: 217.859 | H8: 260.819 | I8: 234.238 | J8: 234.796 | K8: 266.985 | L8: 297.551 | M8: 315.518 | N8: 307.759 | O8: 300.955 | P8: 284.847 | Q8: 254.87 | R8: 346.366 | S8: 378.661 | T8: 373.558 | U8: 354.68 | V8: 332.635 | W8: 276.305 | X8: 306.143 | Y8: 358.521 | Z8: 420.126 | AA8: 432.279 | AB8: 523.988 | AC8: 537.834 | AD8: 327.259 | AE8: 279.216 | AF8: 277.643 | AG8: 330.674 | AH8: 388.139 | AI8: 434.227 | AK8: 345.525 | AL8: 380.964 | AM8: 361.911 | AN8: 319.602 | AO8: 340.297 | AP8: 342.707 | AQ8: 387.185 | AR8: 428.983 | AS8: 412.467 | AT8: 377.597 | AU8: 378.28 | AV8: 380.319 | AW8: 387.765 | AX8: 393.28 | AY8: 387.434 | AZ8: 408.081 | BA8: 483 | BB8: 438 | BC8: 441 | BD8: 425 | BE8: 418 | BF8: 394 | BG8: 521 | BH8: 679 | BI8: 794 | BJ8: 821 | BK8: 855 | BL8: 857 | BM8: 796 | BN8: 797 | BO8: 1090 | BP8: 1417 | BQ8: 1575 | BR8: 1426 | BS8: 1204 | BT8: 1047 | BU8: 979 | BV8: 1128 | BW8: 1401 | BX8: 1495 | BY8: 1826 | BZ8: 1992 | CA8: 2114 | CB8: 2233 | CC8: 2605 | CD8: 3163 | CE8: 3889 | CF8: 4454 | CG8: 5159 | CH8: 4611 | CI8: 4319 | CJ8: 4779 | CK8: 5282 | CL8: 5864 | CM8: 6675 | CN8: 7654 | CO8: 10080 | CP8: 11333
A9: Other Current Assets | B9: 85.311 | C9: 79.681 | D9: 79.815 | E9: 23.642 | F9: 28.915 | G9: 26.384 | H9: 27.32 | I9: 17.8 | J9: 19.55 | K9: 19.589 | L9: 18.341 | M9: 23.084 | N9: 25.134 | O9: 28.021 | P9: 27.214 | Q9: 27.069 | R9: 29.938 | S9: 36.825 | T9: 39.483 | U9: 40.56 | V9: 43.055 | W9: 41.102 | X9: 44.551 | Y9: 54.336 | Z9: 55.428 | AA9: 45.294 | AB9: 43.389 | AC9: 56.299 | AD9: 50.885 | AE9: 70.624 | AF9: 48.174 | AG9: 46.966 | AH9: 44.282 | AI9: 53.301 | AK9: 42.092 | AL9: 46.056 | AM9: 61.206 | AN9: 60.854 | AO9: 99.342 | AP9: 147.442 | AQ9: 103.254 | AR9: 116.128 | AS9: 180.656 | AT9: 168.67 | AU9: 190.312 | AV9: 188.937 | AW9: 138.779 | AX9: 136.263 | AY9: 134.473 | AZ9: 128.831 | BA9: 133 | BB9: 147 | BC9: 148 | BD9: 145 | BE9: 93 | BF9: 119 | BG9: 112 | BH9: 124 | BI9: 118 | BJ9: 113 | BK9: 125 | BL9: 135 | BM9: 86 | BN9: 131 | BO9: 136 | BP9: 159 | BQ9: 136 | BR9: 159 | BS9: 151 | BT9: 149 | BU9: 157 | BV9: 195 | BW9: 215 | BX9: 213 | BY9: 239 | BZ9: 444 | CA9: 452 | CB9: 321 | CC9: 366 | CD9: 636 | CE9: 1176 | CF9: 718 | CG9: 791 | CH9: 872 | CI9: 1389 | CJ9: 1289 | CK9: 13079 | CL9: 4062 | CM9: 4026 | CN9: 3806 | CO9: 3771 | CP9: 3779
A10: Total Current Assets | B10: 1319.064 | C10: 1324.48 | D10: 1346.296 | E10: 1351.602 | F10: 1400.789 | G10: 1446.043 | H10: 1058.104 | I10: 1052.712 | J10: 1116.957 | K10: 1146.294 | L10: 1211.151 | M10: 1304.926 | N10: 1319.657 | O10: 1401.915 | P10: 1449.976 | Q10: 1550.299 | R10: 1722.627 | S10: 1726.289 | T10: 2025.888 | U10: 2031.77 | V10: 2154.233 | W10: 2397.405 | X10: 2756.054 | Y10: 2888.829 | Z10: 2748.993 | AA10: 2814.219 | AB10: 2480.099 | AC10: 2167.958 | AD10: 2020.684 | AE10: 2167.905 | AF10: 2357.716 | AG10: 2480.83 | AH10: 2726.98 | AI10: 2655.962 | AK10: 3226.95 | AL10: 3496.763 | AM10: 3317.557 | AN10: 3500.071 | AO10: 3905.358 | AP10: 4032.116 | AQ10: 4213.851 | AR10: 4424.827 | AS10: 4775.258 | AT10: 4606.616 | AU10: 3922.608 | AV10: 4049.841 | AW10: 5624.711 | AX10: 5273.798 | AY10: 5377.586 | AZ10: 5341.109 | BA10: 5713 | BB10: 5832 | BC10: 5608 | BD10: 5834 | BE10: 6053 | BF10: 5790 | BG10: 6156 | BH10: 8307 | BI10: 8536 | BJ10: 8116 | BK10: 8070 | BL10: 8479 | BM10: 9255 | BN10: 9448 | BO10: 10831 | BP10: 11386 | BQ10: 10557 | BR10: 10629 | BS10: 11391 | BT10: 12420 | BU10: 13690 | BV10: 19584 | BW10: 14681 | BX10: 14393 | BY10: 16055 | BZ10: 18127 | CA10: 25806 | CB10: 25806 | CC10: 28829 | CD10: 29575 | CE10: 27418 | CF10: 23223 | CG10: 23073 | CH10: 24883 | CI10: 28797 | CJ10: 32658 | CK10: 44345 | CL10: 53729 | CM10: 59633 | CN10: 67640 | CO10: 80126 | CP10: 89935
A12: Property, Plant, & Equipment, Gross | B12: 181.708 | C12: 194.019 | D12: 189.219 | E12: 229.083 | F12: 242.835 | G12: 292.876 | H12: 290.161 | I12: 337.875 | J12: 351.061 | K12: 367.65 | L12: 385.721 | M12: 395.822 | N12: 404.684 | O12: 433.228 | P12: 451.948 | Q12: 460.401 | R12: 462.455 | S12: 459.393 | T12: 502.789 | U12: 569.498 | V12: 579.86 | W12: 573.502 | X12: 631.616 | Y12: 753.518 | Z12: 915.766 | AA12: 952.386 | AB12: 964.685 | AC12: 1008.753 | AD12: 601.053 | AE12: 582.914 | AF12: 565.296 | AG12: 1088.483 | AH12: 548.916 | AI12: 542.216 | AK12: 1193.939 | AL12: 553.366 | AM12: 550.896 | AN12: 551.757 | AO12: 1156.528 | AP12: 553.541 | AQ12: 574.056 | AR12: 566.54 | AS12: 1288.782 | AT12: 588.023 | AU12: 578.948 | AV12: 595.418 | AW12: 1282.82 | AX12: 570.802 | AY12: 556.911 | AZ12: 566.601 | BA12: 1179 | BB12: 547 | BC12: 497 | BD12: 477 | BE12: 1100 | BF12: 479 | BG12: 485 | BH12: 503 | BI12: 1191 | BJ12: 539 | BK12: 578 | BL12: 600 | BM12: 1737 | BN12: 1066 | BO12: 1162 | BP12: 1292 | BQ12: 2171 | BR12: 2009 | BS12: 2019 | BT12: 2044 | BU12: 3303 | BV12: 2310 | BW12: 2665 | BX12: 2740 | BY12: 4264 | BZ12: 2995 | CA12: 3165 | CB12: 3339 | CC12: 5510 | CD12: 3772 | CE12: 4085 | CF12: 4701 | CG12: 7539 | CH12: 4834 | CI12: 5034 | CJ12: 5160 | CK12: 8769 | CL12: 5538 | CM12: 6441 | CN12: 7098 | CO12: 12477 | CP12: 8946
A13: Accumulated Depreciation | B13: -50.441 | C13: -50.441 | D13: -50.441 | E13: -93.931 | F13: -93.931 | G13: -93.931 | H13: -93.931 | I13: -147.846 | J13: -166.02 | K13: -184.662 | L13: -203.523 | M13: -216.867 | N13: -235.448 | O13: -254.277 | P13: -273.443 | Q13: -282.249 | R13: -282.249 | S13: -282.249 | T13: -282.249 | U13: -308.67 | V13: -308.67 | W13: -308.67 | X13: -308.67 | Y13: -393.71 | Z13: -393.71 | AA13: -352.908 | AB13: -355.011 | AC13: -382.955 | AG13: -516.625 | AK13: -625.082 | AO13: -596.456 | AS13: -712.638 | AW13: -700.08 | BA13: -622 | BE13: -634 | BI13: -670 | BM13: -740 | BQ13: -767 | BU13: -1011 | BY13: -1408 | CC13: -1903 | CG13: -2694 | CK13: -3509 | CO13: -4401
A14: Property, Plant, & Equipment, Net | B14: 131.267 | C14: 143.578 | D14: 138.778 | E14: 135.152 | F14: 148.904 | G14: 198.945 | H14: 196.23 | I14: 190.029 | J14: 185.041 | K14: 182.988 | L14: 182.198 | M14: 178.955 | N14: 169.236 | O14: 178.951 | P14: 178.505 | Q14: 178.152 | R14: 180.206 | S14: 177.144 | T14: 220.54 | U14: 260.828 | V14: 271.19 | W14: 264.832 | X14: 322.946 | Y14: 359.808 | Z14: 522.056 | AA14: 599.478 | AB14: 609.674 | AC14: 625.798 | AD14: 601.053 | AE14: 582.914 | AF14: 565.296 | AG14: 571.858 | AH14: 548.916 | AI14: 542.216 | AK14: 568.857 | AL14: 553.366 | AM14: 550.896 | AN14: 551.757 | AO14: 560.072 | AP14: 553.541 | AQ14: 574.056 | AR14: 566.54 | AS14: 576.144 | AT14: 588.023 | AU14: 578.948 | AV14: 595.418 | AW14: 582.74 | AX14: 570.802 | AY14: 556.911 | AZ14: 566.601 | BA14: 557 | BB14: 547 | BC14: 497 | BD14: 477 | BE14: 466 | BF14: 479 | BG14: 485 | BH14: 503 | BI14: 521 | BJ14: 539 | BK14: 578 | BL14: 600 | BM14: 997 | BN14: 1066 | BO14: 1162 | BP14: 1292 | BQ14: 1404 | BR14: 2009 | BS14: 2019 | BT14: 2044 | BU14: 2292 | BV14: 2310 | BW14: 2665 | BX14: 2740 | BY14: 2856 | BZ14: 2995 | CA14: 3165 | CB14: 3339 | CC14: 3607 | CD14: 3772 | CE14: 4085 | CF14: 4701 | CG14: 4845 | CH14: 4834 | CI14: 5034 | CJ14: 5160 | CK14: 5260 | CL14: 5538 | CM14: 6441 | CN14: 7098 | CO14: 8076 | CP14: 8946
A15: Goodwill | B15: 82.857 | C15: 80.462 | Q15: 145.317 | R15: 204.603 | S15: 203.657 | T15: 203.679 | U15: 301.425 | V15: 291.077 | W15: 293.383 | X15: 292.934 | Y15: 354.057 | Z15: 371.019 | AA15: 365.8 | AB15: 366.286 | AC15: 369.844 | AD15: 369.844 | AE15: 369.844 | AF15: 369.844 | AG15: 369.844 | AH15: 369.844 | AI15: 369.844 | AK15: 369.844 | AL15: 369.844 | AM15: 593.513 | AN15: 648.053 | AO15: 641.03 | AP15: 641.03 | AQ15: 641.03 | AR15: 641.03 | AS15: 641.03 | AT15: 641.03 | AU15: 641.03 | AV15: 643.179 | AW15: 643.179 | AX15: 643.179 | AY15: 643.179 | AZ15: 643.179 | BA15: 618 | BB15: 618 | BC15: 618 | BD15: 618 | BE15: 618 | BF15: 618 | BG15: 618 | BH15: 618 | BI15: 618 | BJ15: 618 | BK15: 618 | BL15: 618 | BM15: 618 | BN15: 618 | BO15: 618 | BP15: 618 | BQ15: 618 | BR15: 618 | BS15: 618 | BT15: 618 | BU15: 618 | BV15: 628 | BW15: 4193 | BX15: 4193 | BY15: 4193 | BZ15: 4193 | CA15: 4193 | CB15: 4302 | CC15: 4349 | CD15: 4365 | CE15: 4372 | CF15: 4372 | CG15: 4372 | CH15: 4430 | CI15: 4430 | CJ15: 4430 | CK15: 4430 | CL15: 4453 | CM15: 4622 | CN15: 4724 | CO15: 5188 | CP15: 5498
A16: Other Intangible Assets | D16: 78.158 | E16: 76.471 | F16: 82.352 | G16: 79.088 | H16: 153.512 | I16: 148.872 | J16: 148.937 | K16: 143.33 | L16: 138.175 | M16: 135.621 | N16: 135.523 | O16: 131.375 | P16: 152.314 | Q16: 15.421 | R16: 22.989 | S16: 29.428 | T16: 26.538 | U16: 45.511 | V16: 50.914 | W16: 54.735 | X16: 78.173 | Y16: 106.926 | Z16: 125.001 | AA16: 145.148 | AB16: 155.646 | AC16: 147.101 | AD16: 142.446 | AE16: 135.678 | AF16: 127.817 | AG16: 120.458 | AH16: 115.423 | AI16: 118.879 | AK16: 288.745 | AL16: 278.761 | AM16: 358.136 | AN16: 342.839 | AO16: 326.136 | AP16: 363.395 | AQ16: 346.938 | AR16: 331.248 | AS16: 312.332 | AT16: 336.733 | AU16: 322.52 | AV16: 320.589 | AW16: 296.012 | AX16: 277.53 | AY16: 260.613 | AZ16: 241.301 | BA16: 222 | BB16: 205 | BC16: 190 | BD16: 172 | BE16: 166 | BF16: 155 | BG16: 138 | BH16: 120 | BI16: 104 | BJ16: 90 | BK16: 76 | BL16: 63 | BM16: 52 | BN16: 55 | BO16: 51 | BP16: 49 | BQ16: 45 | BR16: 54 | BS16: 49 | BT16: 43 | BU16: 49 | BV16: 80 | BW16: 2854 | BX16: 2861 | BY16: 2737 | BZ16: 2613 | CA16: 2478 | CB16: 2454 | CC16: 2339 | CD16: 2211 | CE16: 2036 | CF16: 1850 | CG16: 1676 | CH16: 1541 | CI16: 1395 | CJ16: 1251 | CK16: 1112 | CL16: 986 | CM16: 952 | CN16: 838 | CO16: 807 | CP16: 769
A17: Equity & Other Investments | AC17: 6.412 | AG17: 6.63 | AK17: 8.792 | AO17: 10.382 | BU17: 77 | BX17: 106 | BY17: 144 | BZ17: 146 | CA17: 147 | CB17: 308 | CC17: 266 | CD17: 285 | CE17: 307 | CF17: 314 | CG17: 299 | CH17: 505 | CI17: 800 | CJ17: 1172 | CK17: 1321 | CL17: 1750 | CM17: 1819 | CN17: 2237 | CO17: 3387 | CP17: 3240
A18: Other Long-Term Assets | B18: 66.529 | C18: 66.634 | D18: 66.465 | E18: 53.79 | F18: 55.488 | G18: 56.037 | H18: 50.934 | I18: 7.731 | J18: 7.255 | K18: 8.277 | L18: 8.132 | M18: 9.034 | N18: 10.678 | O18: 15.977 | P18: 24.713 | Q18: 65.498 | R18: 31.028 | S18: 47.311 | T18: 54.508 | U18: 35.729 | V18: 33.454 | W18: 25.912 | X18: 25.156 | Y18: 38.051 | Z18: 40.389 | AA18: 35.404 | AB18: 37.193 | AC18: 33.614 | AD18: 44.677 | AE18: 42.068 | AF18: 42.901 | AG18: 36.298 | AH18: 41.867 | AI18: 44.367 | AK18: 32.058 | AL18: 38.01 | AM18: 44.322 | AN18: 46.323 | AO18: 109.95 | AP18: 118.085 | AQ18: 116.006 | AR18: 111.499 | AS18: 107.481 | AT18: 107.125 | AU18: 104.486 | AV18: 102.346 | AW18: 104.252 | AX18: 99.354 | AY18: 95.43 | AZ18: 93.679 | BA18: 91 | BB18: 89 | BC18: 66 | BD18: 73 | BE18: 67 | BF18: 66 | BG18: 64 | BH18: 64 | BI18: 62 | BJ18: 47 | BK18: 60 | BL18: 70 | BM18: 319 | BN18: 273 | BO18: 220 | BP18: 312 | BQ18: 668 | BR18: 711 | BS18: 698 | BT18: 685 | BU18: 589 | BV18: 652 | BW18: 787 | BX18: 2588 | BY18: 2806 | BZ18: 2722 | CA18: 2861 | CB18: 4423 | CC18: 4797 | CD18: 5004 | CE18: 5258 | CF18: 6028 | CG18: 6917 | CH18: 8267 | CI18: 9099 | CJ18: 9477 | CK18: 9260 | CL18: 10616 | CM18: 11760 | CN18: 13476 | CO18: 14017 | CP18: 16866
A19: Total Assets | B19: 1599.717 | C19: 1615.154 | D19: 1629.697 | E19: 1617.015 | F19: 1687.533 | G19: 1780.113 | H19: 1458.78 | I19: 1399.344 | J19: 1458.19 | K19: 1480.889 | L19: 1539.656 | M19: 1628.536 | N19: 1635.094 | O19: 1728.218 | P19: 1805.508 | Q19: 1954.687 | R19: 2161.453 | S19: 2183.829 | T19: 2531.153 | U19: 2675.263 | V19: 2800.868 | W19: 3036.267 | X19: 3475.263 | Y19: 3747.671 | Z19: 3807.458 | AA19: 3960.049 | AB19: 3648.898 | AC19: 3350.727 | AD19: 3178.704 | AE19: 3298.409 | AF19: 3463.574 | AG19: 3585.918 | AH19: 3803.03 | AI19: 3731.268 | AK19: 4495.246 | AL19: 4736.744 | AM19: 4864.424 | AN19: 5089.043 | AO19: 5552.928 | AP19: 5708.167 | AQ19: 5891.881 | AR19: 6075.144 | AS19: 6412.245 | AT19: 6279.527 | AU19: 5569.592 | AV19: 5711.373 | AW19: 7250.894 | AX19: 6864.663 | AY19: 6933.719 | AZ19: 6885.869 | BA19: 7201 | BB19: 7291 | BC19: 6979 | BD19: 7174 | BE19: 7370 | BF19: 7108 | BG19: 7461 | BH19: 9612 | BI19: 9841 | BJ19: 9410 | BK19: 9402 | BL19: 9830 | BM19: 11241 | BN19: 11460 | BO19: 12882 | BP19: 13657 | BQ19: 13292 | BR19: 14021 | BS19: 14775 | BT19: 15810 | BU19: 17315 | BV19: 23254 | BW19: 25180 | BX19: 26881 | BY19: 28791 | BZ19: 30796 | CA19: 38650 | CB19: 40632 | CC19: 44187 | CD19: 45212 | CE19: 43476 | CF19: 40488 | CG19: 41182 | CH19: 44460 | CI19: 49555 | CJ19: 54148 | CK19: 65728 | CL19: 77072 | CM19: 85227 | CN19: 96013 | CO19: 111601 | CP19: 125254
A21: Liabilities
A22: Accounts Payable | B22: 190.36 | C22: 165.395 | D22: 170.589 | E22: 141.129 | F22: 234.437 | G22: 282.397 | H22: 242.309 | I22: 185.342 | J22: 214.618 | K22: 223.201 | L22: 262.96 | M22: 238.223 | N22: 182.146 | O22: 221.047 | P22: 179.777 | Q22: 179.395 | R22: 298.147 | S22: 230.916 | T22: 324.396 | U22: 272.075 | V22: 334.046 | W22: 323.381 | X22: 449.792 | Y22: 492.099 | Z22: 427.855 | AA22: 438.892 | AB22: 387.252 | AC22: 218.864 | AD22: 226.114 | AE22: 275.978 | AF22: 321.53 | AG22: 344.527 | AH22: 362.74 | AI22: 280.041 | AK22: 286.138 | AL22: 346.295 | AM22: 297.813 | AN22: 307.943 | AO22: 335.072 | AP22: 395.578 | AQ22: 417.25 | AR22: 390.265 | AS22: 356.428 | AT22: 328.259 | AU22: 310.271 | AV22: 333.283 | AW22: 324.391 | AX22: 309.008 | AY22: 261.627 | AZ22: 328.097 | BA22: 293 | BB22: 222 | BC22: 277 | BD22: 295 | BE22: 296 | BF22: 320 | BG22: 423 | BH22: 523 | BI22: 485 | BJ22: 348 | BK22: 431 | BL22: 511 | BM22: 596 | BN22: 623 | BO22: 800 | BP22: 902 | BQ22: 511 | BR22: 368 | BS22: 437 | BT22: 591 | BU22: 687 | BV22: 761 | BW22: 893 | BX22: 1097 | BY22: 1149 | BZ22: 1218 | CA22: 1474 | CB22: 1664 | CC22: 1783 | CD22: 1999 | CE22: 2421 | CF22: 1491 | CG22: 1193 | CH22: 1141 | CI22: 1929 | CJ22: 2380 | CK22: 2699 | CL22: 2715 | CM22: 3680 | CN22: 5353 | CO22: 6310 | CP22: 7331
A23: Tax Payable | AG23: 1.784 | AK23: 4.576 | AO23: 6.941 | AP23: 9.068 | AQ23: 10.165 | AR23: 10.324 | AS23: 3.173 | AT23: 6.405 | AU23: 6.576 | AV23: 8.349 | AW23: 2.378 | AX23: 4.497 | AY23: 5.81 | AZ23: 5.512 | BA23: 3 | BB23: 4 | BC23: 3 | BD23: 7 | BE23: 2 | BF23: 9 | BG23: 6 | BH23: 9 | BI23: 4 | BJ23: 10 | BK23: 12 | BL23: 11 | BM23: 33 | BN23: 38 | BO23: 39 | BP23: 40 | BQ23: 91 | BR23: 107 | BS23: 37 | BT23: 52 | BU23: 61 | BV23: 74 | BW23: 52 | BX23: 70 | BZ23: 96 | CA23: 64 | CB23: 36 | CC23: 132 | CD23: 736 | CE23: 158 | CF23: 108 | CG23: 467 | CH23: 1544 | CI23: 2803 | CJ23: 420 | CK23: 296 | CL23: 3881 | CM23: 1173 | CN23: 1356 | CO23: 881 | CP23: 5672
A24: Other Accrued Liabilities | B24: 181.928 | C24: 186.157 | D24: 203.832 | E24: 228.467 | F24: 175.344 | G24: 183.196 | H24: 187.405 | I24: 144.755 | J24: 140.89 | K24: 148.797 | L24: 150.833 | M24: 170.577 | N24: 193.029 | O24: 198.867 | P24: 247.39 | Q24: 259.047 | R24: 229.434 | S24: 272.899 | T24: 333.033 | U24: 365.552 | V24: 285.435 | W24: 353.833 | X24: 402.987 | Y24: 469.206 | Z24: 433.989 | AA24: 685.301 | AB24: 613.182 | AC24: 503.477 | AD24: 476.058 | AE24: 615.343 | AF24: 354.034 | AG24: 388.267 | AH24: 402.553 | AI24: 539.098 | AK24: 381.574 | AL24: 634.871 | AM24: 662.486 | AN24: 578.741 | AO24: 281.857 | AP24: 242.712 | AQ24: 290.561 | AR24: 284.702 | AS24: 307.857 | AT24: 287.007 | AU24: 311.377 | AV24: 306.213 | AW24: 163.964 | AX24: 283.43 | AY24: 297.559 | AZ24: 309.537 | BA24: 140 | BB24: 132 | BC24: 189 | BD24: 156 | BE24: 140 | BF24: 115 | BG24: 130 | BH24: 129 | BI24: 199 | BJ24: 119 | BK24: 190 | BL24: 215 | BM24: 420 | BN24: 331 | BO24: 488 | BP24: 529 | BQ24: 574 | BR24: 465 | BS24: 515 | BT24: 526 | BU24: 775 | BV24: 653 | BW24: 953 | BX24: 1090 | BY24: 979 | BZ24: 1158 | CA24: 1392 | CB24: 1372 | CC24: 1605 | CD24: 1673 | CE24: 2750 | CF24: 3044 | CG24: 2946 | CH24: 2494 | CI24: 3355 | CJ24: 3834 | CK24: 4780 | CL24: 5493 | CM24: 6860 | CN24: 7473 | CO24: 8130 | CP24: 9769
A25: Deferred Revenue | B25: 49.369 | C25: 62.42 | D25: 63.495 | M25: 11.5 | O25: 5.584 | Q25: 0.217 | R25: 6.805 | S25: 1.229 | U25: 1.18 | V25: 4.386 | W25: 3.584 | X25: 3.663 | Y25: 5.856 | Z25: 14.708 | AA25: 10.823 | AB25: 4.031 | AC25: 15.417 | AF25: 15.109 | AG25: 19.624 | AK25: 245.596 | AO25: 270.649 | AP25: 272.367 | AQ25: 273.182 | AR25: 269.003 | AS25: 282.695 | AT25: 269.569 | AU25: 267.252 | AV25: 282.658 | AW25: 268.808 | AX25: 275.711 | AY25: 277.033 | AZ25: 258.635 | BA25: 296 | BB25: 377 | BC25: 321 | BD25: 229 | BE25: 322 | BF25: 350 | BG25: 251 | BH25: 170 | BI25: 85 | BJ25: 46 | BK25: 74 | BL25: 65 | BM25: 53 | BN25: 56 | BO25: 77 | BP25: 80 | BQ25: 92 | BR25: 85 | BS25: 127 | BT25: 119 | BU25: 141 | BV25: 174 | BW25: 222 | BX25: 235 | BY25: 288 | BZ25: 333 | CA25: 301 | CB25: 298 | CC25: 300 | CD25: 334 | CE25: 359 | CF25: 338 | CG25: 354 | CH25: 367 | CI25: 421 | CJ25: 513 | CK25: 764 | CL25: 845 | CM25: 948 | CN25: 752 | CO25: 837 | CP25: 1074
A26: Short-term Debt | B26: 3.944 | C26: 5.607 | D26: 5.58 | E26: 5.676 | F26: 6.203 | G26: 6.528 | H26: 5.788 | I26: 4.015 | J26: 3.043 | K26: 2.038 | L26: 1.36 | M26: 0.856 | N26: 0.345 | T26: 0.34 | BE26: 1500 | BF26: 1500 | BG26: 1500 | BH26: 1056 | BI26: 827 | BJ26: 222 | BK26: 86 | BL26: 24 | BM26: 15 | BN26: 14 | BO26: 14 | BP26: 3 | BX26: 998 | BY26: 999 | BZ26: 999 | CA26: 1000 | CE26: 1249 | CF26: 1249 | CG26: 1250 | CH26: 1250 | CI26: 1249 | CJ26: 1249 | CK26: 1250 | CL26: 1250
A27: Deferred Tax Liabilities
A28: Current Portion of Capital Leases | BE28: 4 | BH28: 4 | BI28: 4 | BJ28: 5 | BK28: 5 | BL28: 5 | BR28: 80 | BS28: 84 | BT28: 89 | BU28: 91 | BV28: 100 | BW28: 124 | BX28: 116 | BZ28: 135 | CA28: 132 | CB28: 140 | CC28: 144 | CG28: 176 | CH28: 187 | CI28: 208 | CJ28: 230 | CK28: 228 | CL28: 246 | CM28: 250 | CN28: 273 | CO28: 288 | CP28: 300
A29: Other Current Liabilities | B29: 0.528 | C29: 4.117 | D29: 0.584 | E29: 4.176 | F29: 0.525 | G29: 4.117 | I29: 5.6843419e-14 | T29: -1.1368684e-13 | U29: 1.1368684e-13 | W29: 1.1368684e-13 | Y29: -1.1368684e-13 | AB29: 1.1368684e-13 | AC29: 40.833 | AE29: 1.1368684e-13 | AF29: 198.133 | AG29: 30.176 | AI29: 1.1368684e-13 | AK29: 24.798 | AL29: 1.1368684e-13 | AO29: 35.439 | AP29: 27.679 | AQ29: 30.802 | AR29: 37.065 | AS29: 26.07 | AT29: 34.337 | AU29: 40.315 | AV29: 55.424 | AW29: 185.955 | AX29: 25.299 | AY29: 26.7 | AZ29: 32.126 | BA29: 164 | BB29: 148 | BC29: 146 | BD29: 168 | BE29: 174 | BF29: 162 | BG29: 169 | BH29: 195 | BI29: 215 | BJ29: 240 | BK29: 236 | BL29: 197 | BM29: 36 | BN29: 44 | BO29: 44 | BP29: 54 | BQ29: 61 | BR29: 78 | BS29: 117 | BT29: 98 | BU29: 29 | BV29: 141 | BW29: 166 | BX29: 63 | BY29: 510 | BZ29: 65 | CA29: 85 | CB29: 102 | CC29: 371 | CD29: 820 | CE29: 636 | CF29: 625 | CG29: 177 | CH29: 277 | CI29: 369 | CJ29: 475 | CK29: 614 | CL29: 793 | CM29: 1058 | CN29: 1272 | CO29: 1601 | CP29: 2396
A30: Total Current Liabilities | B30: 426.129 | C30: 423.696 | D30: 444.08 | E30: 379.448 | F30: 416.509 | G30: 476.238 | H30: 435.502 | I30: 334.112 | J30: 358.551 | K30: 374.036 | L30: 415.153 | M30: 421.156 | N30: 375.52 | O30: 425.498 | P30: 427.167 | Q30: 438.659 | R30: 534.386 | S30: 505.044 | T30: 657.769 | U30: 638.807 | V30: 623.867 | W30: 680.798 | X30: 856.442 | Y30: 967.161 | Z30: 876.552 | AA30: 1135.016 | AB30: 1004.465 | AC30: 778.591 | AD30: 702.172 | AE30: 891.321 | AF30: 888.806 | AG30: 784.378 | AH30: 765.293 | AI30: 819.139 | AK30: 942.682 | AL30: 981.166 | AM30: 960.299 | AN30: 886.684 | AO30: 929.958 | AP30: 947.404 | AQ30: 1021.96 | AR30: 991.359 | AS30: 976.223 | AT30: 925.577 | AU30: 935.791 | AV30: 985.927 | AW30: 945.496 | AX30: 897.945 | AY30: 868.729 | AZ30: 933.907 | BA30: 896 | BB30: 883 | BC30: 936 | BD30: 855 | BE30: 2438 | BF30: 2456 | BG30: 2479 | BH30: 2086 | BI30: 1819 | BJ30: 990 | BK30: 1034 | BL30: 1028 | BM30: 1153 | BN30: 1106 | BO30: 1462 | BP30: 1608 | BQ30: 1329 | BR30: 1183 | BS30: 1317 | BT30: 1475 | BU30: 1784 | BV30: 1903 | BW30: 2410 | BX30: 3669 | BY30: 3925 | BZ30: 4004 | CA30: 4448 | CB30: 3612 | CC30: 4335 | CD30: 5562 | CE30: 7573 | CF30: 6855 | CG30: 6563 | CH30: 7260 | CI30: 10334 | CJ30: 9101 | CK30: 10631 | CL30: 15223 | CM30: 13969 | CN30: 16479 | CO30: 18047 | CP30: 26542
A32: Long-term Debt | B32: 300 | C32: 300 | D32: 300 | E32: 300 | F32: 300 | G32: 300 | N32: 8.233 | AW32: 1356.375 | AX32: 1363.276 | AY32: 1370.249 | AZ32: 1377.259 | BA32: 1384 | BB32: 1391 | BC32: 1399 | BD32: 1406 | BH32: 1982 | BI32: 1983 | BJ32: 1984 | BK32: 1984 | BL32: 1985 | BM32: 1985 | BN32: 1986 | BO32: 1987 | BP32: 1987 | BQ32: 1988 | BR32: 1988 | BS32: 1989 | BT32: 1990 | BU32: 1991 | BV32: 6959 | BW32: 6960 | BX32: 5963 | BY32: 5964 | BZ32: 5964 | CA32: 10943 | CB32: 10944 | CC32: 10946 | CD32: 10947 | CE32: 9700 | CF32: 9701 | CG32: 9703 | CH32: 9704 | CI32: 8456 | CJ32: 8457 | CK32: 8459 | CL32: 8460 | CM32: 8461 | CN32: 8462 | CO32: 8463 | CP32: 8464
A33: Capital Lease Obligations | B33: 4.937 | C33: 7.926 | D33: 6.34 | E33: 4.88 | F33: 4.194 | G33: 3.522 | H33: 2.634 | I33: 0.856 | J33: 0.345 | AC33: 25.634 | AD33: 25.351 | AE33: 25.06 | AF33: 24.76 | AG33: 24.45 | AH33: 24.098 | AI33: 23.734 | AK33: 23.389 | AL33: 22.957 | AM33: 22.493 | AN33: 21.949 | AO33: 21.439 | AP33: 20.83 | AQ33: 20.237 | AR33: 19.627 | AS33: 18.998 | AT33: 18.333 | AU33: 17.685 | AV33: 17.015 | AW33: 17.5 | AX33: 16.683 | AY33: 15.842 | AZ33: 14.977 | BA33: 14 | BB33: 13 | BC33: 12 | BD33: 11 | BE33: 10 | BF33: 9 | BG33: 8 | BH33: 7 | BJ33: 4 | BK33: 3 | BL33: 1 | BR33: 486 | BS33: 483 | BT33: 469 | BU33: 561 | BV33: 519 | BW33: 611 | BX33: 604 | BY33: 634 | BZ33: 640 | CA33: 716 | CB33: 743 | CC33: 741 | CD33: 752 | CE33: 743 | CF33: 798 | CG33: 902 | CH33: 939 | CI33: 1041 | CJ33: 1091 | CK33: 1119 | CL33: 1281 | CM33: 1304 | CN33: 1490 | CO33: 1519 | CP33: 1521
A34: Pension Liabilities | BI34: 10 | BK34: 11 | BL34: 11 | BM34: 12 | BN34: 18 | BO34: 18 | BP34: 19 | BQ34: 20 | BR34: 21 | BS34: 22 | BT34: 22 | BU34: 22 | BV34: 23 | BW34: 38 | BX34: 40 | BZ34: 34 | CA34: 37 | CB34: 38
A35: Deferred Revenue | H35: 6.38 | I35: 8.609 | J35: 8.609 | K35: 8.609 | L35: 8.609 | M35: 20.754 | N35: 20.754 | O35: 20.754 | P35: 20.754 | R35: 8.26 | W35: 31.897 | X35: 59.898 | Y35: 86.9 | Z35: 114.596 | AA35: 88.956 | AB35: 85.007 | AC35: 75.252 | AF35: 106.406 | AG35: 17.739 | AK35: 209.129 | AL35: 153.127 | AM35: 61.728 | AO35: 333.658 | AP35: 267.342 | AQ35: 211.337 | AR35: 174.248 | AS35: 429.102 | AT35: 362.555 | AU35: 301.05 | AV35: 242.619 | AW35: 330.152 | AX35: 281.405 | AY35: 232.765 | AZ35: 210.388 | BA35: 340 | BB35: 296 | BC35: 293 | BD35: 326 | BE35: 345 | BF35: 334 | BG35: 373 | BH35: 90 | BI35: 151 | BJ35: 164 | BK35: 266 | BL35: 313 | BM35: 42 | BN35: 49 | BO35: 62 | BP35: 80 | BQ35: 86 | BR35: 70 | BS35: 77 | BT35: 82 | BU35: 89 | BV35: 99 | BW35: 394 | BX35: 405 | BY35: 404 | BZ35: 407 | CA35: 418 | CB35: 416 | CC35: 447 | CD35: 460 | CE35: 453 | CF35: 459 | CG35: 465 | CH35: 520 | CI35: 681 | CJ35: 849 | CK35: 1035 | CL35: 1287 | CM35: 1470 | CN35: 1623 | CO35: 1862 | CP35: 2086
A36: Other Long-Term Liabilities | C36: -1.1368684e-13 | F36: 6 | G36: 4.5 | H36: 4.582 | I36: 4.582 | J36: 4.582 | K36: 3.082 | L36: 7.483 | M36: 8.358 | O36: 6.733 | P36: 8.146 | Q36: 20.036 | R36: 10.156 | S36: 24.237 | T36: 27.667 | U36: 29.537 | V36: 81.107 | W36: 63.294 | X36: 80.997 | Y36: 75.698 | Z36: 79.132 | AA36: 73.162 | AB36: 72.351 | AC36: 76.598 | AD36: 132.305 | AE36: 134.619 | AF36: 19.967 | AG36: 94.211 | AH36: 152.994 | AI36: 127.881 | AK36: 138.584 | AL36: 131.686 | AM36: 130.435 | AN36: 206.96 | AO36: 122.149 | AP36: 185.163 | AQ36: 184.682 | AR36: 167.064 | AS36: 160.219 | AT36: 148.126 | AU36: 142.893 | AV36: 145.165 | AW36: 144.973 | AX36: 138.369 | AY36: 141.348 | AZ36: 144.745 | BA36: 149 | BB36: 152 | BC36: 154 | BD36: 111 | BE36: 108 | BF36: 113 | BG36: 121 | BH36: 123 | BI36: 116 | BJ36: 136 | BK36: 131 | BL36: 140 | BM36: 578 | BN36: 584 | BO36: 558 | BP36: 488 | BQ36: 527 | BR36: 569 | BS36: 551 | BT36: 558 | BU36: 664 | BV36: 652 | BW36: 853 | BX36: 866 | BY36: 971 | BZ36: 973 | CA36: 941 | CB36: 1081 | CC36: 1106 | CD36: 1171 | CE36: 1156 | CF36: 1326 | CG36: 1448 | CH36: 1517 | CI36: 1542 | CJ36: 1385 | CK36: 1506 | CL36: 1679 | CM36: 1866 | CN36: 2060 | CO36: 2383 | CP36: 2798
A37: Total Liabilities | B37: 731.066 | C37: 731.622 | D37: 750.42 | E37: 684.328 | F37: 726.703 | G37: 784.26 | H37: 449.098 | I37: 348.159 | J37: 372.087 | K37: 385.727 | L37: 431.245 | M37: 450.268 | N37: 404.507 | O37: 452.985 | P37: 456.067 | Q37: 458.695 | R37: 552.802 | S37: 529.281 | T37: 685.436 | U37: 668.344 | V37: 704.974 | W37: 775.989 | X37: 997.337 | Y37: 1129.759 | Z37: 1070.28 | AA37: 1297.134 | AB37: 1161.823 | AC37: 956.075 | AD37: 859.828 | AE37: 1051 | AF37: 1039.939 | AG37: 920.778 | AH37: 942.385 | AI37: 970.754 | AK37: 1313.784 | AL37: 1288.936 | AM37: 1174.955 | AN37: 1115.593 | AO37: 1407.204 | AP37: 1420.739 | AQ37: 1438.216 | AR37: 1352.298 | AS37: 1584.542 | AT37: 1454.591 | AU37: 1397.419 | AV37: 1390.726 | AW37: 2794.496 | AX37: 2697.678 | AY37: 2628.933 | AZ37: 2681.276 | BA37: 2783 | BB37: 2735 | BC37: 2794 | BD37: 2709 | BE37: 2901 | BF37: 2912 | BG37: 2981 | BH37: 4288 | BI37: 4079 | BJ37: 3278 | BK37: 3429 | BL37: 3478 | BM37: 3770 | BN37: 3743 | BO37: 4087 | BP37: 4182 | BQ37: 3950 | BR37: 4317 | BS37: 4439 | BT37: 4596 | BU37: 5111 | BV37: 10155 | BW37: 11266 | BX37: 11547 | BY37: 11898 | BZ37: 12022 | CA37: 17503 | CB37: 16834 | CC37: 17575 | CD37: 18892 | CE37: 19625 | CF37: 19139 | CG37: 19081 | CH37: 19940 | CI37: 22054 | CJ37: 20883 | CK37: 22750 | CL37: 27930 | CM37: 27070 | CN37: 30114 | CO37: 32274 | CP37: 41411
A39: Shareholders' Equity
A40: Additional Paid-in Capital | B40: 478.481 | C40: 485.762 | D40: 529.992 | E40: 531.03 | F40: 539.031 | G40: 551.067 | H40: 567.186 | I40: 583.481 | J40: 598.66 | K40: 603.014 | L40: 613.326 | M40: 636.618 | N40: 672.102 | O40: 691.914 | P40: 740.665 | Q40: 965.604 | R40: 907.097 | S40: 1117.121 | T40: 1200.723 | U40: 1295.65 | V40: 1377.513 | W40: 1493.24 | X40: 1598.291 | Y40: 1654.681 | Z40: 1727.519 | AA40: 1776.698 | AB40: 1841.85 | AC40: 1889.257 | AD40: 2013.746 | AE40: 2043.84 | AF40: 2111.506 | AG40: 2219.401 | AH40: 2288.989 | AI40: 2329.456 | AK40: 2500.577 | AL40: 2638.531 | AM40: 2725.317 | AN40: 2846.266 | AO40: 2900.896 | AP40: 2994.507 | AQ40: 3040.979 | AR40: 3114.995 | AS40: 3193.623 | AT40: 3273.23 | AU40: 3104.501 | AV40: 3407.889 | AW40: 3483.342 | AX40: 3492.14 | AY40: 3682.742 | AZ40: 3783.099 | BA40: 3855 | BB40: 3986 | BC40: 3938 | BD40: 4170 | BE40: 4170 | BF40: 4218 | BG40: 4408 | BH40: 4581 | BI40: 4708 | BJ40: 4936 | BK40: 5048 | BL40: 5219 | BM40: 5351 | BN40: 5546 | BO40: 5681 | BP40: 5891 | BQ40: 6051 | BR40: 6317 | BS40: 6543 | BT40: 6824 | BU40: 7045 | BV40: 7354 | BW40: 7828 | BX40: 8301 | BY40: 8719 | BZ40: 9280 | CA40: 9745 | CB40: 10465 | CC40: 10385 | CD40: 10623 | CE40: 10968 | CF40: 11565 | CG40: 11971 | CH40: 12453 | CI40: 12629 | CJ40: 12991 | CK40: 13109 | CL40: 12651 | CM40: 12115 | CN40: 11821 | CO40: 11237 | CP40: 11475
A41: Retained Earnings | B41: 390.185 | C41: 395.438 | D41: 346.802 | E41: 397.739 | F41: 417.486 | G41: 441.636 | H41: 447.992 | I41: 472.158 | J41: 493.507 | K41: 498.626 | L41: 524.505 | M41: 572.514 | N41: 636.958 | O41: 711.795 | P41: 777.048 | Q41: 747.731 | R41: 965.776 | S41: 926.548 | T41: 1033.059 | U41: 1196.565 | V41: 1328.824 | W41: 1501.556 | X41: 1737.217 | Y41: 1994.21 | Z41: 2171.015 | AA41: 2050.086 | AB41: 2111.834 | AC41: 1964.169 | AD41: 1762.831 | AE41: 1657.529 | AF41: 1765.106 | AG41: 1896.182 | AH41: 2033.776 | AI41: 1892.815 | AK41: 2149.328 | AL41: 2284.547 | AM41: 2436.12 | AN41: 2614.393 | AO41: 2730.418 | AP41: 2790.855 | AQ41: 2909.901 | AR41: 3118.981 | AS41: 3246.088 | AT41: 3277.713 | AU41: 3330.815 | AV41: 3406.154 | AW41: 3504.742 | AX41: 3594.527 | AY41: 3675.071 | AZ41: 3801.966 | BA41: 3949 | BB41: 4037 | BC41: 4010 | BD41: 4204 | BE41: 4350 | BF41: 4484 | BG41: 4675 | BH41: 5529 | BI41: 6108 | BJ41: 6506 | BK41: 7006 | BL41: 7760 | BM41: 8787 | BN41: 9948 | BO41: 10957 | BP41: 12096 | BQ41: 12565 | BR41: 12862 | BS41: 13317 | BT41: 14118 | BU41: 14971 | BV41: 15790 | BW41: 16313 | BX41: 17550 | BY41: 18908 | BZ41: 20721 | CA41: 22995 | CB41: 25359 | CC41: 16235 | CD41: 15758 | CE41: 12971 | CF41: 9905 | CG41: 10171 | CH41: 12115 | CI41: 14921 | CJ41: 20360 | CK41: 29817 | CL41: 36598 | CM41: 45961 | CN41: 53950 | CO41: 68038 | CP41: 72158
A42: Treasury Stock | L42: -24.644 | M42: -24.644 | N42: -72.1 | O42: -122.142 | P42: -162.142 | Q42: -212.142 | R42: -262.142 | S42: -387.12 | T42: -387.12 | U42: -487.12 | V42: -612.12 | W42: -736.506 | X42: -861.547 | Y42: -1039.632 | Z42: -1163.528 | AA42: -1163.528 | AB42: -1463.268 | AC42: -1463.268 | AD42: -1463.268 | AE42: -1463.268 | AF42: -1463.268 | AG42: -1463.268 | AH42: -1473.655 | AI42: -1473.656 | AK42: -1479.392 | AL42: -1487.079 | AM42: -1487.093 | AN42: -1496.904 | AO42: -1496.904 | AP42: -1509.088 | AQ42: -1509.087 | AR42: -1522.709 | AS42: -1622.709 | AT42: -1737.025 | AU42: -2269.766 | AV42: -2499.99 | AW42: -2537.295 | AX42: -2926.789 | AY42: -3058.149 | AZ42: -3390.985 | BA42: -3395 | BB42: -3476 | BC42: -3765 | BD42: -3912 | BE42: -4048 | BF42: -4508 | BG42: -4608 | BH42: -4783 | BI42: -5039 | BJ42: -5297 | BK42: -6070 | BL42: -6614 | BM42: -6650 | BN42: -7755 | BO42: -7821 | BP42: -8489 | BQ42: -9263 | BR42: -9474 | BS42: -9524 | BT42: -9726 | BU42: -9814 | BV42: -10036 | BW42: -10232 | BX42: -10530 | BY42: -10756 | BZ42: -11242 | CA42: -11604 | CB42: -12038
A43: Common Stock | X43: 1 | Y43: 1 | Z43: 1 | AA43: 1 | AB43: 1 | AC43: 1 | AD43: 1 | AE43: 1 | AF43: 1 | AG43: 1 | AH43: 1 | AI43: 1 | AK43: 1 | AL43: 1 | AM43: 1 | AN43: 1 | AO43: 1 | AP43: 1 | AQ43: 1 | AR43: 1 | AS43: 1 | AT43: 1 | AU43: 1 | AV43: 1 | AW43: 1 | AX43: 1 | AY43: 1 | AZ43: 1 | BA43: 1 | BB43: 1 | BC43: 1 | BD43: 1 | BE43: 1 | BF43: 1 | BG43: 1 | BH43: 1 | BI43: 1 | BJ43: 1 | BK43: 1 | BL43: 1 | BM43: 1 | BN43: 1 | BO43: 1 | BP43: 1 | BQ43: 1 | BR43: 1 | BS43: 1 | BT43: 1 | BU43: 1 | BV43: 1 | BW43: 1 | BX43: 1 | BY43: 3 | BZ43: 1 | CA43: 3 | CB43: 3 | CC43: 3 | CD43: 3 | CE43: 2 | CF43: 2 | CG43: 2 | CH43: 2 | CI43: 2 | CJ43: 2 | CK43: 25 | CL43: 2 | CM43: 25 | CN43: 25 | CO43: 24 | CP43: 24
A44: Preferred Stock
A45: Accumulated Other Comprehensive Income | B45: -0.166 | C45: 2.179 | D45: 2.326 | E45: 3.76 | F45: 4.154 | G45: 2.989 | H45: -5.658 | I45: -4.618 | J45: -6.23 | K45: -6.645 | L45: -4.944 | M45: -6.389 | N45: -6.546 | O45: -6.508 | P45: -6.308 | Q45: -5.561 | R45: -2.451 | S45: -2.374 | T45: -1.325 | U45: 1.436 | V45: 1.284 | W45: 1.586 | X45: 3.35 | Y45: 8.034 | Z45: 1.549 | AA45: -0.966 | AB45: -3.97 | AC45: 3.865 | AD45: 4.931 | AE45: 8.67 | AF45: 9.645 | AG45: 12.172 | AH45: 10.872 | AI45: 11.234 | AK45: 10.272 | AL45: 11.121 | AM45: 14.434 | AN45: 8.997 | AO45: 10.614 | AP45: 10.447 | AQ45: 11.159 | AR45: 10.86 | AS45: 9.981 | AT45: 10.293 | AU45: 5.897 | AV45: 5.862 | AW45: 4.877 | AX45: 6.364 | AY45: 4.378 | AZ45: 9.761 | BA45: 8 | BB45: 8 | BC45: 1 | BD45: 2 | BE45: -4 | BF45: 1 | BG45: 4 | BH45: -4 | BI45: -16 | BJ45: -14 | BK45: -12 | BL45: -14 | BM45: -18 | BN45: -23 | BO45: -23 | BP45: -24 | BQ45: -12 | BR45: -2 | BS45: -1 | BT45: -3 | BU45: 1 | BV45: -10 | BW45: 4 | BX45: 12 | BY45: 19 | BZ45: 14 | CA45: 8 | CB45: 9 | CC45: -11 | CD45: -64 | CE45: -90 | CF45: -123 | CG45: -43 | CH45: -50 | CI45: -51 | CJ45: -88 | CK45: 27 | CL45: -109 | CM45: 56 | CN45: 103 | CO45: 28 | CP45: 186
...

Sheet Share Price 5y
C2: Datum | D2: Eröffnungspreis
C3: 43990 | D3: 8.877
C4: 43991 | D4: 8.8
C5: 43992 | D5: 9.168
C6: 43993 | D6: 9.15
C7: 43994 | D7: 9.163
C8: 43997 | D8: 8.815
C9: 43998 | D9: 9.225
C10: 43999 | D10: 9.114
C11: 44000 | D11: 9.227
C12: 44001 | D12: 9.243
C13: 44004 | D13: 9.3
C14: 44005 | D14: 9.551
... C1259: 45814 | D1259: 142.51
